Workbook

Sheet DATA
A1: Ship To | B1: Ship To Name | C1: Purchase Order Number | D1: Sales Order | E1: Requested Delivery Date | F1: SYSPRO Purchase Order | G1: Line Number | H1: Warehouse | I1: Material | J1: Material Description | K1: Delivery Quantity | L1: Delivery Unit | M1: Bin Location | N1: Batch Code | O1: Batch Expiration Date | P1: Reference/GRN | Q1: Receipt Date | R1: Batch Status | S1: Expected Release Date
A2: 5432038 | B2: Fast Distribution Corporation | C2: GBOR22024Wk8PD1NST1 | D2: 4064824610 | E2: 45342 | I2: 12584775 | J2: NESTEA Apple 24(6x20g) PR 5+1 PH | K2: 2 | L2: CS | N2: 40290604E1 | O2: 45688
A3: 5432038 | B3: Fast Distribution Corporation | C3: GBOR22024Wk8PD1NST1 | D3: 4064824610 | E3: 45342 | I3: 12584786 | J3: NESTEA Lemon 24(6x20g) PR 5+1 PH | K3: 2 | L3: CS | N3: 40360604F1 | O3: 45716
A4: 5432038 | B4: Fast Distribution Corporation | C4: GBOR22024Wk8PD1NST1 | D4: 4064824610 | E4: 45342 | I4: 12537538 | J4: NESTEA Lemon 12(12x20g) PRFrPitcher PH | K4: 2 | L4: CS | N4: 40200604F2 | O4: 45688
A5: 5432038 | B5: Fast Distribution Corporation | C5: GBOR22024Wk8PD1NST1 | D5: 4064824610 | E5: 45342 | I5: 12538256 | J5: NESTEA Apple 12(12x20g) PRFrPitcher PH | K5: 3 | L5: CS | N5: 40260604E2 | O5: 45688
A6: Ship To | B6: Ship To Name | C6: Purchase Order Number | D6: Sales Order | E6: Requested Delivery Date | F6: SYSPRO Purchase Order | G6: Line Number | H6: Warehouse | I6: Material | J6: Material Description | K6: Delivery Quantity | L6: Delivery Unit | M6: Bin Location | N6: Batch Code | O6: Batch Expiration Date | P6: Reference/GRN | Q6: Receipt Date | R6: Batch Status | S6: Expected Release Date
A7: 5432038 | B7: Fast Distribution Corporation | C7: GBOR21324PLMXS7 | D7: 4064969826 | E7: 45342 | I7: 12531347 | J7: NESCAFE Creamylatte Twinpack 200x51g PH | K7: 0 | L7: CS
A8: 5432038 | B8: Fast Distribution Corporation | C8: GBOR21324PLMXS7 | D8: 4064969826 | E8: 45342 | I8: 12531347 | J8: NESCAFE Creamylatte Twinpack 200x51g PH | K8: 64 | L8: CS | N8: 40170597T1 | O8: 45688
A9: 5432038 | B9: Fast Distribution Corporation | C9: GBOR21324PLMXS7 | D9: 4064969826 | E9: 45342 | I9: 12531347 | J9: NESCAFE Creamylatte Twinpack 200x51g PH | K9: 26 | L9: CS | N9: 40170597U1 | O9: 45688
A10: 5432038 | B10: Fast Distribution Corporation | C10: GBOR21324PLMXS7 | D10: 4064969826 | E10: 45342 | I10: 12531347 | J10: NESCAFE Creamylatte Twinpack 200x51g PH | K10: 9 | L10: CS | N10: 40180597U1 | O10: 45688
A11: 5432038 | B11: Fast Distribution Corporation | C11: GBOR21324PLMXS7 | D11: 4064969826 | E11: 45342 | I11: 12531524 | J11: NESCAFE Creamy White Twinpack 200x51g PH | K11: 0 | L11: CS
A12: 5432038 | B12: Fast Distribution Corporation | C12: GBOR21324PLMXS7 | D12: 4064969826 | E12: 45342 | I12: 12531524 | J12: NESCAFE Creamy White Twinpack 200x51g PH | K12: 11 | L12: CS | N12: 33390597E1 | O12: 45657
A13: 5432038 | B13: Fast Distribution Corporation | C13: GBOR21324PLMXS7 | D13: 4064969826 | E13: 45342 | I13: 12531524 | J13: NESCAFE Creamy White Twinpack 200x51g PH | K13: 31 | L13: CS | N13: 33540597F1 | O13: 45657
A14: 5432038 | B14: Fast Distribution Corporation | C14: GBOR21324PLMXS7 | D14: 4064969826 | E14: 45342 | I14: 12531524 | J14: NESCAFE Creamy White Twinpack 200x51g PH | K14: 109 | L14: CS | N14: 33610597U1 | O14: 45657
A15: Ship To | B15: Ship To Name | C15: Purchase Order Number | D15: Sales Order | E15: Requested Delivery Date | F15: SYSPRO Purchase Order | G15: Line Number | H15: Warehouse | I15: Material | J15: Material Description | K15: Delivery Quantity | L15: Delivery Unit | M15: Bin Location | N15: Batch Code | O15: Batch Expiration Date | P15: Reference/GRN | Q15: Receipt Date | R15: Batch Status | S15: Expected Release Date
A16: 5432038 | B16: Fast Distribution Corporation | C16: GBOR21324CFM2 | D16: 4064977532 | E16: 45342 | I16: 12540289 | J16: COFFEE-MATE 72x80g PH | K16: 3 | L16: CS | N16: 4003643821 | O16: 45777
A17: 5432038 | B17: Fast Distribution Corporation | C17: GBOR21324CFM2 | D17: 4064977532 | E17: 45342 | I17: 12536823 | J17: COFFEE-MATE 60x150g PH | K17: 6 | L17: CS | N17: 4043643831 | O17: 45808
A18: 5432038 | B18: Fast Distribution Corporation | C18: GBOR21324CFM2 | D18: 4064977532 | E18: 45342 | I18: 12536774 | J18: COFFEE-MATE 40x220g PH | K18: 6 | L18: CS | N18: 4039643841 | O18: 45808
A19: Ship To | B19: Ship To Name | C19: Purchase Order Number | D19: Sales Order | E19: Requested Delivery Date | F19: SYSPRO Purchase Order | G19: Line Number | H19: Warehouse | I19: Material | J19: Material Description | K19: Delivery Quantity | L19: Delivery Unit | M19: Bin Location | N19: Batch Code | O19: Batch Expiration Date | P19: Reference/GRN | Q19: Receipt Date | R19: Batch Status | S19: Expected Release Date
A20: 5432038 | B20: Fast Distribution Corporation | C20: GBOR21424STKAL | D20: 4064927933 | E20: 45342 | I20: 12550969 | J20: NESCAFE CLAS Sticks MP 21(48x1.9g) N1 PH | K20: 0 | L20: CS
A21: 5432038 | B21: Fast Distribution Corporation | C21: GBOR21424STKAL | D21: 4064927933 | E21: 45342 | I21: 12550969 | J21: NESCAFE CLAS Sticks MP 21(48x1.9g) N1 PH | K21: 24 | L21: CS | N21: 40318985C1 | O21: 45777
A22: 5432038 | B22: Fast Distribution Corporation | C22: GBOR21424STKAL | D22: 4064927933 | E22: 45342 | I22: 12550969 | J22: NESCAFE CLAS Sticks MP 21(48x1.9g) N1 PH | K22: 8 | L22: CS | N22: 40320604G1 | O22: 45808
A23: 5432038 | B23: Fast Distribution Corporation | C23: GBOR21424STKAL | D23: 4064927933 | E23: 45342 | I23: 12550969 | J23: NESCAFE CLAS Sticks MP 21(48x1.9g) N1 PH | K23: 168 | L23: CS | N23: 40330604G1 | O23: 45808
A24: Ship To | B24: Ship To Name | C24: Purchase Order Number | D24: Sales Order | E24: Requested Delivery Date | F24: SYSPRO Purchase Order | G24: Line Number | H24: Warehouse | I24: Material | J24: Material Description | K24: Delivery Quantity | L24: Delivery Unit | M24: Bin Location | N24: Batch Code | O24: Batch Expiration Date | P24: Reference/GRN | Q24: Receipt Date | R24: Batch Status | S24: Expected Release Date
A25: 5432038 | B25: Fast Distribution Corporation | C25: GBOR21324CLM2 | D25: 4064945681 | E25: 45342 | I25: 12495804 | J25: NESTLE CARNATION Condensada 48x388g PH | K25: 3 | L25: CS | N25: 336015507A | O25: 45652
A26: Ship To | B26: Ship To Name | C26: Purchase Order Number | D26: Sales Order | E26: Requested Delivery Date | F26: SYSPRO Purchase Order | G26: Line Number | H26: Warehouse | I26: Material | J26: Material Description | K26: Delivery Quantity | L26: Delivery Unit | M26: Bin Location | N26: Batch Code | O26: Batch Expiration Date | P26: Reference/GRN | Q26: Receipt Date | R26: Batch Status | S26: Expected Release Date
A27: 5432038 | B27: Fast Distribution Corporation | C27: WBOR21324BNA22 | D27: 4064960784 | E27: 45342 | I27: 12530670 | J27: BONNA 4x2kg PH | K27: 3 | L27: CS | N27: 402173514 | O27: 45961
A28: Ship To | B28: Ship To Name | C28: Purchase Order Number | D28: Sales Order | E28: Requested Delivery Date | F28: SYSPRO Purchase Order | G28: Line Number | H28: Warehouse | I28: Material | J28: Material Description | K28: Delivery Quantity | L28: Delivery Unit | M28: Bin Location | N28: Batch Code | O28: Batch Expiration Date | P28: Reference/GRN | Q28: Receipt Date | R28: Batch Status | S28: Expected Release Date
A29: 5432038 | B29: Fast Distribution Corporation | C29: WBOR2062024BNK4N22 | D29: 4064807579 | E29: 45342 | I29: 12530648 | J29: BONAKID 4x2.4kg N2 PH | K29: 0 | L29: CS
A30: 5432038 | B30: Fast Distribution Corporation | C30: WBOR2062024BNK4N22 | D30: 4064807579 | E30: 45342 | I30: 12530648 | J30: BONAKID 4x2.4kg N2 PH | K30: 4 | L30: CS | N30: 4032735171 | O30: 45991
A31: 5432038 | B31: Fast Distribution Corporation | C31: WBOR2062024BNK4N22 | D31: 4064807579 | E31: 45342 | I31: 12530648 | J31: BONAKID 4x2.4kg N2 PH | K31: 2 | L31: CS | N31: 403373517 | O31: 45991
A32: Ship To | B32: Ship To Name | C32: Purchase Order Number | D32: Sales Order | E32: Requested Delivery Date | F32: SYSPRO Purchase Order | G32: Line Number | H32: Warehouse | I32: Material | J32: Material Description | K32: Delivery Quantity | L32: Delivery Unit | M32: Bin Location | N32: Batch Code | O32: Batch Expiration Date | P32: Reference/GRN | Q32: Receipt Date | R32: Batch Status | S32: Expected Release Date
A33: 5432038 | B33: Fast Distribution Corporation | C33: GBOR2062024CFM2 | D33: 4064863403 | E33: 45342 | I33: 12536784 | J33: COFFEE-MATE 24x400g PH | K33: 10 | L33: CS | N33: 4031643841 | O33: 45777
A34: 5432038 | B34: Fast Distribution Corporation | C34: GBOR2062024CFM2 | D34: 4064863403 | E34: 45342 | I34: 12536774 | J34: COFFEE-MATE 40x220g PH | K34: 15 | L34: CS | N34: 4039643841 | O34: 45808
A35: Ship To | B35: Ship To Name | C35: Purchase Order Number | D35: Sales Order | E35: Requested Delivery Date | F35: SYSPRO Purchase Order | G35: Line Number | H35: Warehouse | I35: Material | J35: Material Description | K35: Delivery Quantity | L35: Delivery Unit | M35: Bin Location | N35: Batch Code | O35: Batch Expiration Date | P35: Reference/GRN | Q35: Receipt Date | R35: Batch Status | S35: Expected Release Date
A36: 5432038 | B36: Fast Distribution Corporation | C36: GBOR2062024CLM2 | D36: 4064859142 | E36: 45342 | I36: 12495804 | J36: NESTLE CARNATION Condensada 48x388g PH | K36: 3 | L36: CS | N36: 336015507A | O36: 45652
A37: Ship To | B37: Ship To Name | C37: Purchase Order Number | D37: Sales Order | E37: Requested Delivery Date | F37: SYSPRO Purchase Order | G37: Line Number | H37: Warehouse | I37: Material | J37: Material Description | K37: Delivery Quantity | L37: Delivery Unit | M37: Bin Location | N37: Batch Code | O37: Batch Expiration Date | P37: Reference/GRN | Q37: Receipt Date | R37: Batch Status | S37: Expected Release Date
A38: 5432038 | B38: Fast Distribution Corporation | C38: GBOR2062024PLMIL4 | D38: 4064880034 | E38: 45342 | I38: 12435172 | J38: MILO ACTIV-GO Winner 504x24g PH | K38: 50 | L38: CS | N38: 40190604D1 | O38: 45626
A39: Ship To | B39: Ship To Name | C39: Purchase Order Number | D39: Sales Order | E39: Requested Delivery Date | F39: SYSPRO Purchase Order | G39: Line Number | H39: Warehouse | I39: Material | J39: Material Description | K39: Delivery Quantity | L39: Delivery Unit | M39: Bin Location | N39: Batch Code | O39: Batch Expiration Date | P39: Reference/GRN | Q39: Receipt Date | R39: Batch Status | S39: Expected Release Date
A40: 5432038 | B40: Fast Distribution Corporation | C40: GBOR21424MXSAL | D40: 4064928568 | E40: 45342 | I40: 12557556 | J40: NESC CreamyLatteTwin 20(10x51g)PR9+1PH | K40: 20 | L40: CS | N40: 40090597T1 | O40: 45688
...

Sheet PRINT
A1: CHECKED BY:
A2: PLATE NO:
A3: DATE-TIME START-END UNLOADING:
A4: =DATA!C1 | B4: =DATA!I1 | C4: =DATA!J1 | D4: =DATA!K1 | E4: =DATA!M1 | F4: =DATA!N1 | G4: =DATA!O1 | H4: FILTER
A5: =DATA!C2 | B5: =DATA!I2 | C5: =DATA!J2 | D5: =DATA!K2 | F5: =DATA!N2 | G5: =DATA!O2 | H5: TRUE
A6: =DATA!C3 | B6: =DATA!I3 | C6: =DATA!J3 | D6: =DATA!K3 | F6: =DATA!N3 | G6: =DATA!O3 | H6: TRUE
A7: =DATA!C4 | B7: =DATA!I4 | C7: =DATA!J4 | D7: =DATA!K4 | F7: =DATA!N4 | G7: =DATA!O4 | H7: TRUE
A8: =DATA!C5 | B8: =DATA!I5 | C8: =DATA!J5 | D8: =DATA!K5 | F8: =DATA!N5 | G8: =DATA!O5 | H8: TRUE
A9: =DATA!C6 | B9: =DATA!I6 | C9: =DATA!J6 | D9: =DATA!K6 | F9: =DATA!N6 | G9: =DATA!O6 | H9: TRUE
A10: =DATA!C7 | B10: =DATA!I7 | C10: =DATA!J7 | D10: =DATA!K7 | F10: =DATA!N7 | G10: =DATA!O7 | H10: TRUE
A11: =DATA!C8 | B11: =DATA!I8 | C11: =DATA!J8 | D11: =DATA!K8 | F11: =DATA!N8 | G11: =DATA!O8 | H11: TRUE
A12: =DATA!C9 | B12: =DATA!I9 | C12: =DATA!J9 | D12: =DATA!K9 | F12: =DATA!N9 | G12: =DATA!O9 | H12: TRUE
A13: =DATA!C10 | B13: =DATA!I10 | C13: =DATA!J10 | D13: =DATA!K10 | F13: =DATA!N10 | G13: =DATA!O10 | H13: TRUE
A14: =DATA!C11 | B14: =DATA!I11 | C14: =DATA!J11 | D14: =DATA!K11 | F14: =DATA!N11 | G14: =DATA!O11 | H14: TRUE
A15: =DATA!C12 | B15: =DATA!I12 | C15: =DATA!J12 | D15: =DATA!K12 | F15: =DATA!N12 | G15: =DATA!O12 | H15: TRUE
A16: =DATA!C13 | B16: =DATA!I13 | C16: =DATA!J13 | D16: =DATA!K13 | F16: =DATA!N13 | G16: =DATA!O13 | H16: TRUE
... A253: =DATA!C250 | B253: =DATA!I250 | C253: =DATA!J250 | D253: =DATA!K250 | F253: =DATA!N250 | G253: =DATA!O250 | H253: TRUE

Sheet COMPARISON
A1: Material | B1: Material Description | C1: ACTUAL | D1: SYSTEM | E1: VARIANCE | F1: REMARKS | G1: Correction
A2: 12540289 | B2: =VLOOKUP($A2,DATA!$I:$J,2,FALSE) | C2: =SUMIFS(PRINT!$D:$D,PRINT!$B:$B,COMPARISON!A:A,PRINT!H:H,"TRUE") | D2: =SUMIFS(DATA!$K:$K,DATA!$I:$I,COMPARISON!$A:$A) | E2: =C2-D2+G2 | F2: =IF($E2=0,"-",IF($E2>0,"OVER","SHORT"))
A3: 12489220 | B3: =VLOOKUP($A3,DATA!$I:$J,2,FALSE) | C3: =SUMIFS(PRINT!$D:$D,PRINT!$B:$B,COMPARISON!A:A,PRINT!H:H,"TRUE") | D3: =SUMIFS(DATA!$K:$K,DATA!$I:$I,COMPARISON!$A:$A) | E3: =C3-D3+G3 | F3: =IF($E3=0,"-",IF($E3>0,"OVER","SHORT"))
A4: 12413317 | B4: =VLOOKUP($A4,DATA!$I:$J,2,FALSE) | C4: =SUMIFS(PRINT!$D:$D,PRINT!$B:$B,COMPARISON!A:A,PRINT!H:H,"TRUE") | D4: =SUMIFS(DATA!$K:$K,DATA!$I:$I,COMPARISON!$A:$A) | E4: =C4-D4+G4 | F4: =IF($E4=0,"-",IF($E4>0,"OVER","SHORT"))
A5: 12498699 | B5: =VLOOKUP($A5,DATA!$I:$J,2,FALSE) | C5: =SUMIFS(PRINT!$D:$D,PRINT!$B:$B,COMPARISON!A:A,PRINT!H:H,"TRUE") | D5: =SUMIFS(DATA!$K:$K,DATA!$I:$I,COMPARISON!$A:$A) | E5: =C5-D5+G5 | F5: =IF($E5=0,"-",IF($E5>0,"OVER","SHORT"))
A6: 12571148 | B6: =VLOOKUP($A6,DATA!$I:$J,2,FALSE) | C6: =SUMIFS(PRINT!$D:$D,PRINT!$B:$B,COMPARISON!A:A,PRINT!H:H,"TRUE") | D6: =SUMIFS(DATA!$K:$K,DATA!$I:$I,COMPARISON!$A:$A) | E6: =C6-D6+G6 | F6: =IF($E6=0,"-",IF($E6>0,"OVER","SHORT"))
A7: 12396047 | B7: =VLOOKUP($A7,DATA!$I:$J,2,FALSE) | C7: =SUMIFS(PRINT!$D:$D,PRINT!$B:$B,COMPARISON!A:A,PRINT!H:H,"TRUE") | D7: =SUMIFS(DATA!$K:$K,DATA!$I:$I,COMPARISON!$A:$A) | E7: =C7-D7+G7 | F7: =IF($E7=0,"-",IF($E7>0,"OVER","SHORT"))
A8: 12538256 | B8: =VLOOKUP($A8,DATA!$I:$J,2,FALSE) | C8: =SUMIFS(PRINT!$D:$D,PRINT!$B:$B,COMPARISON!A:A,PRINT!H:H,"TRUE") | D8: =SUMIFS(DATA!$K:$K,DATA!$I:$I,COMPARISON!$A:$A) | E8: =C8-D8+G8 | F8: =IF($E8=0,"-",IF($E8>0,"OVER","SHORT"))
A9: 12572305 | B9: =VLOOKUP($A9,DATA!$I:$J,2,FALSE) | C9: =SUMIFS(PRINT!$D:$D,PRINT!$B:$B,COMPARISON!A:A,PRINT!H:H,"TRUE") | D9: =SUMIFS(DATA!$K:$K,DATA!$I:$I,COMPARISON!$A:$A) | E9: =C9-D9+G9 | F9: =IF($E9=0,"-",IF($E9>0,"OVER","SHORT"))
A10: 12531347 | B10: =VLOOKUP($A10,DATA!$I:$J,2,FALSE) | C10: =SUMIFS(PRINT!$D:$D,PRINT!$B:$B,COMPARISON!A:A,PRINT!H:H,"TRUE") | D10: =SUMIFS(DATA!$K:$K,DATA!$I:$I,COMPARISON!$A:$A) | E10: =C10-D10+G10 | F10: =IF($E10=0,"-",IF($E10>0,"OVER","SHORT"))
A11: 12562968 | B11: =VLOOKUP($A11,DATA!$I:$J,2,FALSE) | C11: =SUMIFS(PRINT!$D:$D,PRINT!$B:$B,COMPARISON!A:A,PRINT!H:H,"TRUE") | D11: =SUMIFS(DATA!$K:$K,DATA!$I:$I,COMPARISON!$A:$A) | E11: =C11-D11+G11 | F11: =IF($E11=0,"-",IF($E11>0,"OVER","SHORT"))
A12: 12396061 | B12: =VLOOKUP($A12,DATA!$I:$J,2,FALSE) | C12: =SUMIFS(PRINT!$D:$D,PRINT!$B:$B,COMPARISON!A:A,PRINT!H:H,"TRUE") | D12: =SUMIFS(DATA!$K:$K,DATA!$I:$I,COMPARISON!$A:$A) | E12: =C12-D12+G12 | F12: =IF($E12=0,"-",IF($E12>0,"OVER","SHORT"))
A13: 12454174 | B13: =VLOOKUP($A13,DATA!$I:$J,2,FALSE) | C13: =SUMIFS(PRINT!$D:$D,PRINT!$B:$B,COMPARISON!A:A,PRINT!H:H,"TRUE") | D13: =SUMIFS(DATA!$K:$K,DATA!$I:$I,COMPARISON!$A:$A) | E13: =C13-D13+G13 | F13: =IF($E13=0,"-",IF($E13>0,"OVER","SHORT"))
... A17: 12452538 | B17: =VLOOKUP($A17,DATA!$I:$J,2,FALSE) | C17: =SUMIFS(PRINT!$D:$D,PRINT!$B:$B,COMPARISON!A:A,PRINT!H:H,"TRUE") | D17: =SUMIFS(DATA!$K:$K,DATA!$I:$I,COMPARISON!$A:$A) | E17: =C17-D17+G17 | F17: =IF($E17=0,"-",IF($E17>0,"OVER","SHORT"))
A18: Material | B18: =VLOOKUP($A18,DATA!$I:$J,2,FALSE) | C18: =SUMIFS(PRINT!$D:$D,PRINT!$B:$B,COMPARISON!A:A,PRINT!H:H,"TRUE") | D18: =SUMIFS(DATA!$K:$K,DATA!$I:$I,COMPARISON!$A:$A) | E18: =C18-D18+G18 | F18: =IF($E18=0,"-",IF($E18>0,"OVER","SHORT"))
A19: 12495804 | B19: =VLOOKUP($A19,DATA!$I:$J,2,FALSE) | C19: =SUMIFS(PRINT!$D:$D,PRINT!$B:$B,COMPARISON!A:A,PRINT!H:H,"TRUE") | D19: =SUMIFS(DATA!$K:$K,DATA!$I:$I,COMPARISON!$A:$A) | E19: =C19-D19+G19 | F19: =IF($E19=0,"-",IF($E19>0,"OVER","SHORT"))
A20: 12551613 | B20: =VLOOKUP($A20,DATA!$I:$J,2,FALSE) | C20: =SUMIFS(PRINT!$D:$D,PRINT!$B:$B,COMPARISON!A:A,PRINT!H:H,"TRUE") | D20: =SUMIFS(DATA!$K:$K,DATA!$I:$I,COMPARISON!$A:$A) | E20: =C20-D20+G20 | F20: =IF($E20=0,"-",IF($E20>0,"OVER","SHORT"))
A21: 12537538 | B21: =VLOOKUP($A21,DATA!$I:$J,2,FALSE) | C21: =SUMIFS(PRINT!$D:$D,PRINT!$B:$B,COMPARISON!A:A,PRINT!H:H,"TRUE") | D21: =SUMIFS(DATA!$K:$K,DATA!$I:$I,COMPARISON!$A:$A) | E21: =C21-D21+G21 | F21: =IF($E21=0,"-",IF($E21>0,"OVER","SHORT"))
A22: 12531524 | B22: =VLOOKUP($A22,DATA!$I:$J,2,FALSE) | C22: =SUMIFS(PRINT!$D:$D,PRINT!$B:$B,COMPARISON!A:A,PRINT!H:H,"TRUE") | D22: =SUMIFS(DATA!$K:$K,DATA!$I:$I,COMPARISON!$A:$A) | E22: =C22-D22+G22 | F22: =IF($E22=0,"-",IF($E22>0,"OVER","SHORT"))
A23: 12536774 | B23: =VLOOKUP($A23,DATA!$I:$J,2,FALSE) | C23: =SUMIFS(PRINT!$D:$D,PRINT!$B:$B,COMPARISON!A:A,PRINT!H:H,"TRUE") | D23: =SUMIFS(DATA!$K:$K,DATA!$I:$I,COMPARISON!$A:$A) | E23: =C23-D23+G23 | F23: =IF($E23=0,"-",IF($E23>0,"OVER","SHORT"))
A24: 12584775 | B24: =VLOOKUP($A24,DATA!$I:$J,2,FALSE) | C24: =SUMIFS(PRINT!$D:$D,PRINT!$B:$B,COMPARISON!A:A,PRINT!H:H,"TRUE") | D24: =SUMIFS(DATA!$K:$K,DATA!$I:$I,COMPARISON!$A:$A) | E24: =C24-D24+G24 | F24: =IF($E24=0,"-",IF($E24>0,"OVER","SHORT"))
A25: 12530636 | B25: =VLOOKUP($A25,DATA!$I:$J,2,FALSE) | C25: =SUMIFS(PRINT!$D:$D,PRINT!$B:$B,COMPARISON!A:A,PRINT!H:H,"TRUE") | D25: =SUMIFS(DATA!$K:$K,DATA!$I:$I,COMPARISON!$A:$A) | E25: =C25-D25+G25 | F25: =IF($E25=0,"-",IF($E25>0,"OVER","SHORT"))
A26: 12530637 | B26: =VLOOKUP($A26,DATA!$I:$J,2,FALSE) | C26: =SUMIFS(PRINT!$D:$D,PRINT!$B:$B,COMPARISON!A:A,PRINT!H:H,"TRUE") | D26: =SUMIFS(DATA!$K:$K,DATA!$I:$I,COMPARISON!$A:$A) | E26: =C26-D26+G26 | F26: =IF($E26=0,"-",IF($E26>0,"OVER","SHORT"))
A27: 12470863 | B27: =VLOOKUP($A27,DATA!$I:$J,2,FALSE) | C27: =SUMIFS(PRINT!$D:$D,PRINT!$B:$B,COMPARISON!A:A,PRINT!H:H,"TRUE") | D27: =SUMIFS(DATA!$K:$K,DATA!$I:$I,COMPARISON!$A:$A) | E27: =C27-D27+G27 | F27: =IF($E27=0,"-",IF($E27>0,"OVER","SHORT"))
A28: 12536784 | B28: =VLOOKUP($A28,DATA!$I:$J,2,FALSE) | C28: =SUMIFS(PRINT!$D:$D,PRINT!$B:$B,COMPARISON!A:A,PRINT!H:H,"TRUE") | D28: =SUMIFS(DATA!$K:$K,DATA!$I:$I,COMPARISON!$A:$A) | E28: =C28-D28+G28 | F28: =IF($E28=0,"-",IF($E28>0,"OVER","SHORT"))
A29: 12584786 | B29: =VLOOKUP($A29,DATA!$I:$J,2,FALSE) | C29: =SUMIFS(PRINT!$D:$D,PRINT!$B:$B,COMPARISON!A:A,PRINT!H:H,"TRUE") | D29: =SUMIFS(DATA!$K:$K,DATA!$I:$I,COMPARISON!$A:$A) | E29: =C29-D29+G29 | F29: =IF($E29=0,"-",IF($E29>0,"OVER","SHORT"))
A30: 12530648 | B30: =VLOOKUP($A30,DATA!$I:$J,2,FALSE) | C30: =SUMIFS(PRINT!$D:$D,PRINT!$B:$B,COMPARISON!A:A,PRINT!H:H,"TRUE") | D30: =SUMIFS(DATA!$K:$K,DATA!$I:$I,COMPARISON!$A:$A) | E30: =C30-D30+G30 | F30: =IF($E30=0,"-",IF($E30>0,"OVER","SHORT"))
... A38: 12578169 | B38: =VLOOKUP($A38,DATA!$I:$J,2,FALSE) | C38: =SUMIFS(PRINT!$D:$D,PRINT!$B:$B,COMPARISON!A:A,PRINT!H:H,"TRUE") | D38: =SUMIFS(DATA!$K:$K,DATA!$I:$I,COMPARISON!$A:$A) | E38: =C38-D38+G38 | F38: =IF($E38=0,"-",IF($E38>0,"OVER","SHORT"))
B39: =VLOOKUP($A39,DATA!$I:$J,2,FALSE) | C39: =SUMIFS(PRINT!$D:$D,PRINT!$B:$B,COMPARISON!A:A,PRINT!H:H,"TRUE") | D39: =SUMIFS(DATA!$K:$K,DATA!$I:$I,COMPARISON!$A:$A) | E39: =C39-D39+G39 | F39: =IF($E39=0,"-",IF($E39>0,"OVER","SHORT"))
B40: =VLOOKUP($A40,DATA!$I:$J,2,FALSE) | C40: =SUMIFS(PRINT!$D:$D,PRINT!$B:$B,COMPARISON!A:A,PRINT!H:H,"TRUE") | D40: =SUMIFS(DATA!$K:$K,DATA!$I:$I,COMPARISON!$A:$A) | E40: =C40-D40+G40 | F40: =IF($E40=0,"-",IF($E40>0,"OVER","SHORT"))
B41: =VLOOKUP($A41,DATA!$I:$J,2,FALSE) | C41: =SUMIFS(PRINT!$D:$D,PRINT!$B:$B,COMPARISON!A:A,PRINT!H:H,"TRUE") | D41: =SUMIFS(DATA!$K:$K,DATA!$I:$I,COMPARISON!$A:$A) | E41: =C41-D41+G41 | F41: =IF($E41=0,"-",IF($E41>0,"OVER","SHORT"))
B42: =VLOOKUP($A42,DATA!$I:$J,2,FALSE) | C42: =SUMIFS(PRINT!$D:$D,PRINT!$B:$B,COMPARISON!A:A,PRINT!H:H,"TRUE") | D42: =SUMIFS(DATA!$K:$K,DATA!$I:$I,COMPARISON!$A:$A) | E42: =C42-D42+G42 | F42: =IF($E42=0,"-",IF($E42>0,"OVER","SHORT"))
B43: =VLOOKUP($A43,DATA!$I:$J,2,FALSE) | C43: =SUMIFS(PRINT!$D:$D,PRINT!$B:$B,COMPARISON!A:A,PRINT!H:H,"TRUE") | D43: =SUMIFS(DATA!$K:$K,DATA!$I:$I,COMPARISON!$A:$A) | E43: =C43-D43+G43 | F43: =IF($E43=0,"-",IF($E43>0,"OVER","SHORT"))
B44: =VLOOKUP($A44,DATA!$I:$J,2,FALSE) | C44: =SUMIFS(PRINT!$D:$D,PRINT!$B:$B,COMPARISON!A:A,PRINT!H:H,"TRUE") | D44: =SUMIFS(DATA!$K:$K,DATA!$I:$I,COMPARISON!$A:$A) | E44: =C44-D44+G44 | F44: =IF($E44=0,"-",IF($E44>0,"OVER","SHORT"))
B45: =VLOOKUP($A45,DATA!$I:$J,2,FALSE) | C45: =SUMIFS(PRINT!$D:$D,PRINT!$B:$B,COMPARISON!A:A,PRINT!H:H,"TRUE") | D45: =SUMIFS(DATA!$K:$K,DATA!$I:$I,COMPARISON!$A:$A) | E45: =C45-D45+G45 | F45: =IF($E45=0,"-",IF($E45>0,"OVER","SHORT"))
B46: =VLOOKUP($A46,DATA!$I:$J,2,FALSE) | C46: =SUMIFS(PRINT!$D:$D,PRINT!$B:$B,COMPARISON!A:A,PRINT!H:H,"TRUE") | D46: =SUMIFS(DATA!$K:$K,DATA!$I:$I,COMPARISON!$A:$A) | E46: =C46-D46+G46 | F46: =IF($E46=0,"-",IF($E46>0,"OVER","SHORT"))
B47: =VLOOKUP($A47,DATA!$I:$J,2,FALSE) | C47: =SUMIFS(PRINT!$D:$D,PRINT!$B:$B,COMPARISON!A:A,PRINT!H:H,"TRUE") | D47: =SUMIFS(DATA!$K:$K,DATA!$I:$I,COMPARISON!$A:$A) | E47: =C47-D47+G47 | F47: =IF($E47=0,"-",IF($E47>0,"OVER","SHORT"))
B48: =VLOOKUP($A48,DATA!$I:$J,2,FALSE) | C48: =SUMIFS(PRINT!$D:$D,PRINT!$B:$B,COMPARISON!A:A,PRINT!H:H,"TRUE") | D48: =SUMIFS(DATA!$K:$K,DATA!$I:$I,COMPARISON!$A:$A) | E48: =C48-D48+G48 | F48: =IF($E48=0,"-",IF($E48>0,"OVER","SHORT"))
B49: =VLOOKUP($A49,DATA!$I:$J,2,FALSE) | C49: =SUMIFS(PRINT!$D:$D,PRINT!$B:$B,COMPARISON!A:A,PRINT!H:H,"TRUE") | D49: =SUMIFS(DATA!$K:$K,DATA!$I:$I,COMPARISON!$A:$A) | E49: =C49-D49+G49 | F49: =IF($E49=0,"-",IF($E49>0,"OVER","SHORT"))
B50: =VLOOKUP($A50,DATA!$I:$J,2,FALSE) | C50: =SUMIFS(PRINT!$D:$D,PRINT!$B:$B,COMPARISON!A:A,PRINT!H:H,"TRUE") | D50: =SUMIFS(DATA!$K:$K,DATA!$I:$I,COMPARISON!$A:$A) | E50: =C50-D50+G50 | F50: =IF($E50=0,"-",IF($E50>0,"OVER","SHORT"))
...
